Workbook

Sheet 1. 가정
A1: 새싹지원사업 — 3년 매출 시뮬레이션
A2: 단위: 만원 (10,000원). 셀 색깔: 파랑=입력값, 검정=공식, 노랑배경=핵심 가정. 입력 바꾸면 모든 시트 자동 갱신.
A4: 현재 시나리오 (1=보수, 2=기본, 3=공격) | D4: 2 | E4: =CHOOSE(D4,"보수","기본","공격") -> 기본
A6: [① 정부 지원사업 자금]
A7: 사업명 | B7: 보수 (만) | C7: 기본 (만) | D7: 공격 (만) | E7: 도착 분기 | F7: 비고
A8: 예비창업패키지 | B8: 5000 | C8: 10000 | D8: 10000 | E8: Q2 | F8: 최대 1억 사업화 자금
A9: 청년창업사관학교 | B9: 0 | C9: 5000 | D9: 10000 | E9: Q3 | F9: 최대 1억 + 입주 + 멘토링
A10: 딥테크 헬스케어 패키지 | B10: 0 | C10: 0 | D10: 10000 | E10: Q4 | F10: 최대 3억 (1/3만 인정)
A11: 강화군 청년창업 지원금 | B11: 500 | C11: 500 | D11: 500 | E11: Q2 | F11: 강화군 소상공인 지원
A12: 합계 (예상) | B12: =SUM(B8:B11) -> 5500 | C12: =SUM(C8:C11) -> 15500 | D12: =SUM(D8:D11) -> 30500 | F12: 1년차에 도착
A14: [② B2B 지자체 라이선스]
A15: 지표 | B15: 보수 | C15: 기본 | D15: 공격 | F15: 비고
A16: ARPU (연간 단가, 만원) | B16: 500 | C16: 800 | D16: 1500 | F16: 강화군 표준
A17: Y1 신규 계약 (곳) | B17: 1 | C17: 1 | D17: 2 | F17: Q2~Q4 강화 + α
A18: Y2 신규 계약 (곳) | B18: 1 | C18: 3 | D18: 5 | F18: 인천창경 + 타지자체
A19: Y3 신규 계약 (곳) | B19: 2 | C19: 4 | D19: 8 | F19: 전국 확장
A20: 이탈률 (연간) | B20: 0 | C20: 0.1 | D20: 0.15 | F20: 낮을수록 좋음
A23: [③ 사업계획서 AI 컨설팅 (1회 결제)]
A24: 지표 | B24: 보수 | C24: 기본 | D24: 공격 | F24: 비고
A25: 단가 (만원) | B25: 3 | C25: 5 | D25: 8 | F25: 1회 결제
A26: Y1 누적 결제 건수 | B26: 100 | C26: 300 | D26: 600 | F26: M+4 출시 후
A27: Y2 누적 결제 건수 | B27: 400 | C27: 1200 | D27: 2400
A28: Y3 누적 결제 건수 | B28: 1000 | C28: 3000 | D28: 6000
A29: AI 토큰 비용 (회당, 원) | B29: 500 | C29: 500 | D29: 500 | F29: 거의 무시
A31: [④ B2C 프리미엄 구독]
A32: 지표 | B32: 보수 | C32: 기본 | D32: 공격 | F32: 비고
A33: 월 구독료 (원) | B33: 9900 | C33: 14900 | D33: 19900 | F33: 표준 SaaS
A34: Y1 말 유료 구독자 | B34: 50 | C34: 200 | D34: 500 | F34: M+6 베타 오픈 후
A35: Y2 말 유료 구독자 | B35: 300 | C35: 1000 | D35: 2500
A36: Y3 말 유료 구독자 | B36: 800 | C36: 2500 | D36: 6000
A37: 이탈률 (월) | B37: 0.1 | C37: 0.07 | D37: 0.05 | F37: 낮을수록 LTV 높음
A39: [⑤ 비용 구조 (모든 시나리오 공통, 월 단위)]
A40: 항목 | B40: Y1 (월) | C40: Y2 (월) | D40: Y3 (월) | F40: 비고
A41: 호스팅·인프라 (만) | B41: 10 | C41: 30 | D41: 60 | F41: Vercel/AWS, 사용자 비례
A42: AI API (매칭, 만) | B42: 5 | C42: 30 | D42: 100 | F42: Claude Haiku 등 저렴 모델
A43: 도메인·SaaS 도구 (만) | B43: 2 | C43: 5 | D43: 10 | F43: 도메인·분석툴·결제PG 등
A44: 마케팅·콘텐츠 (만) | B44: 20 | C44: 100 | D44: 200 | F44: 콘텐츠 외주·SNS 광고
A45: 운영자 인건비 (만) | B45: 0 | C45: 300 | D45: 500 | F45: Y2부터 본격 풀타임
A46: 외주 인건비 (만) | B46: 0 | C46: 100 | D46: 200 | F46: 콘텐츠·디자인 외주
A47: 월 비용 합계 | B47: =SUM(B41:B46) -> 37 | C47: =SUM(C41:C46) -> 565 | D47: =SUM(D41:D46) -> 1070
...

Sheet 2. 매출 빌드업
A1: 매출 빌드업 — 분기별 (Y1~Y3, 12분기)
A2: 현재 시나리오: | B2: ='1. 가정'!E4 -> 기본
A4: 수익원 | B4: Q1 | C4: Q2 | D4: Q3 | E4: Q4 | F4: Q5 | G4: Q6 | H4: Q7 | I4: Q8 | J4: Q9 | K4: Q10 | L4: Q11 | M4: Q12 | N4: 합계
A6: ① 정부 지원사업 자금
A7: 예비창업패키지 | B7: 0 | C7: =CHOOSE('1. 가정'!$D$4,'1. 가정'!B8,'1. 가정'!C8,'1. 가정'!D8) -> 10000 | D7: 0 | E7: 0 | F7: 0 | G7: 0 | H7: 0 | I7: 0 | J7: 0 | K7: 0 | L7: 0 | M7: 0 | N7: =SUM(B7:M7) -> 10000
A8: 청년창업사관학교 | B8: 0 | C8: 0 | D8: =CHOOSE('1. 가정'!$D$4,'1. 가정'!B9,'1. 가정'!C9,'1. 가정'!D9) -> 5000 | E8: 0 | F8: 0 | G8: 0 | H8: 0 | I8: 0 | J8: 0 | K8: 0 | L8: 0 | M8: 0 | N8: =SUM(B8:M8) -> 5000
A9: 딥테크 헬스케어 | B9: 0 | C9: 0 | D9: 0 | E9: =CHOOSE('1. 가정'!$D$4,'1. 가정'!B10,'1. 가정'!C10,'1. 가정'!D10) -> 0 | F9: 0 | G9: 0 | H9: 0 | I9: 0 | J9: 0 | K9: 0 | L9: 0 | M9: 0 | N9: =SUM(B9:M9) -> 0
A10: 강화군 소상공인 | B10: 0 | C10: =CHOOSE('1. 가정'!$D$4,'1. 가정'!B11,'1. 가정'!C11,'1. 가정'!D11) -> 500 | D10: 0 | E10: 0 | F10: 0 | G10: 0 | H10: 0 | I10: 0 | J10: 0 | K10: 0 | L10: 0 | M10: 0 | N10: =SUM(B10:M10) -> 500
A11: ① 소계 | B11: =SUM(B7:B10) -> 0 | C11: =SUM(C7:C10) -> 10500 | D11: =SUM(D7:D10) -> 5000 | E11: =SUM(E7:E10) -> 0 | F11: =SUM(F7:F10) -> 0 | G11: =SUM(G7:G10) -> 0 | H11: =SUM(H7:H10) -> 0 | I11: =SUM(I7:I10) -> 0 | ... N11: =SUM(N7:N10) -> 15500
A13: ② B2B 지자체 라이선스
A14: 신규 계약 (곳) | B14: 0 | C14: =(CHOOSE('1. 가정'!$D$4,'1. 가정'!B17,'1. 가정'!C17,'1. 가정'!D17))/3 -> 0.33333333 | D14: =(CHOOSE('1. 가정'!$D$4,'1. 가정'!B17,'1. 가정'!C17,'1. 가정'!D17))/3 -> 0.33333333 | E14: =(CHOOSE('1. 가정'!$D$4,'1. 가정'!B17,'1. 가정'!C17,'1. 가정'!D17))/3 -> 0.33333333 | F14: =(CHOOSE('1. 가정'!$D$4,'1. 가정'!B18,'1. 가정'!C18,'1. 가정'!D18))/4 -> 0.75 | G14: =(CHOOSE('1. 가정'!$D$4,'1. 가정'!B18,'1. 가정'!C18,'1. 가정'!D18))/4 -> 0.75 | H14: =(CHOOSE('1. 가정'!$D$4,'1. 가정'!B18,'1. 가정'!C18,'1. 가정'!D18))/4 -> 0.75 | I14: =(CHOOSE('1. 가정'!$D$4,'1. 가정'!B18,'1. 가정'!C18,'1. 가정'!D18))/4 -> 0.75 | J14: =(CHOOSE('1. 가정'!$D$4,'1. 가정'!B19,'1. 가정'!C19,'1. 가정'!D19))/4 -> 1 | K14: =(CHOOSE('1. 가정'!$D$4,'1. 가정'!B19,'1. 가정'!C19,'1. 가정'!D19))/4 -> 1 | L14: =(CHOOSE('1. 가정'!$D$4,'1. 가정'!B19,'1. 가정'!C19,'1. 가정'!D19))/4 -> 1 | M14: =(CHOOSE('1. 가정'!$D$4,'1. 가정'!B19,'1. 가정'!C19,'1. 가정'!D19))/4 -> 1 | N14: =SUM(B14:M14) -> 8
A15: 누적 계약 (분기말) | B15: =B14 -> 0 | C15: =B15*(1-(CHOOSE('1. 가정'!$D$4,'1. 가정'!B20,'1. 가정'!C20,'1. 가정'!D20))/4)+C14 -> 0.33333333 | D15: =C15*(1-(CHOOSE('1. 가정'!$D$4,'1. 가정'!B20,'1. 가정'!C20,'1. 가정'!D20))/4)+D14 -> 0.65833333 | E15: =D15*(1-(CHOOSE('1. 가정'!$D$4,'1. 가정'!B20,'1. 가정'!C20,'1. 가정'!D20))/4)+E14 -> 0.97520833 | F15: =E15*(1-(CHOOSE('1. 가정'!$D$4,'1. 가정'!B20,'1. 가정'!C20,'1. 가정'!D20))/4)+F14 -> 1.7008281 | G15: =F15*(1-(CHOOSE('1. 가정'!$D$4,'1. 가정'!B20,'1. 가정'!C20,'1. 가정'!D20))/4)+G14 -> 2.4083074 | H15: =G15*(1-(CHOOSE('1. 가정'!$D$4,'1. 가정'!B20,'1. 가정'!C20,'1. 가정'!D20))/4)+H14 -> 3.0980997 | I15: =H15*(1-(CHOOSE('1. 가정'!$D$4,'1. 가정'!B20,'1. 가정'!C20,'1. 가정'!D20))/4)+I14 -> 3.7706472 | J15: =I15*(1-(CHOOSE('1. 가정'!$D$4,'1. 가정'!B20,'1. 가정'!C20,'1. 가정'!D20))/4)+J14 -> 4.6763811 | K15: =J15*(1-(CHOOSE('1. 가정'!$D$4,'1. 가정'!B20,'1. 가정'!C20,'1. 가정'!D20))/4)+K14 -> 5.5594715 | L15: =K15*(1-(CHOOSE('1. 가정'!$D$4,'1. 가정'!B20,'1. 가정'!C20,'1. 가정'!D20))/4)+L14 -> 6.4204847 | M15: =L15*(1-(CHOOSE('1. 가정'!$D$4,'1. 가정'!B20,'1. 가정'!C20,'1. 가정'!D20))/4)+M14 -> 7.2599726
A16: B2B 매출 (만) | B16: =B15*(CHOOSE('1. 가정'!$D$4,'1. 가정'!B16,'1. 가정'!C16,'1. 가정'!D16))/4 -> 0 | C16: =C15*(CHOOSE('1. 가정'!$D$4,'1. 가정'!B16,'1. 가정'!C16,'1. 가정'!D16))/4 -> 66.666667 | D16: =D15*(CHOOSE('1. 가정'!$D$4,'1. 가정'!B16,'1. 가정'!C16,'1. 가정'!D16))/4 -> 131.66667 | E16: =E15*(CHOOSE('1. 가정'!$D$4,'1. 가정'!B16,'1. 가정'!C16,'1. 가정'!D16))/4 -> 195.04167 | F16: =F15*(CHOOSE('1. 가정'!$D$4,'1. 가정'!B16,'1. 가정'!C16,'1. 가정'!D16))/4 -> 340.16562 | G16: =G15*(CHOOSE('1. 가정'!$D$4,'1. 가정'!B16,'1. 가정'!C16,'1. 가정'!D16))/4 -> 481.66148 | H16: =H15*(CHOOSE('1. 가정'!$D$4,'1. 가정'!B16,'1. 가정'!C16,'1. 가정'!D16))/4 -> 619.61995 | I16: =I15*(CHOOSE('1. 가정'!$D$4,'1. 가정'!B16,'1. 가정'!C16,'1. 가정'!D16))/4 -> 754.12945 | J16: =J15*(CHOOSE('1. 가정'!$D$4,'1. 가정'!B16,'1. 가정'!C16,'1. 가정'!D16))/4 -> 935.27621 | K16: =K15*(CHOOSE('1. 가정'!$D$4,'1. 가정'!B16,'1. 가정'!C16,'1. 가정'!D16))/4 -> 1111.8943 | L16: =L15*(CHOOSE('1. 가정'!$D$4,'1. 가정'!B16,'1. 가정'!C16,'1. 가정'!D16))/4 -> 1284.0969 | M16: =M15*(CHOOSE('1. 가정'!$D$4,'1. 가정'!B16,'1. 가정'!C16,'1. 가정'!D16))/4 -> 1451.9945 | N16: =SUM(B16:M16) -> 7372.2135
A18: ③ 사업계획서 AI 컨설팅
A19: 분기별 결제 건수 | B19: 0 | C19: =(CHOOSE('1. 가정'!$D$4,'1. 가정'!B26,'1. 가정'!C26,'1. 가정'!D26))*0.1 -> 30 | D19: =(CHOOSE('1. 가정'!$D$4,'1. 가정'!B26,'1. 가정'!C26,'1. 가정'!D26))*0.35 -> 105 | E19: =(CHOOSE('1. 가정'!$D$4,'1. 가정'!B26,'1. 가정'!C26,'1. 가정'!D26))*0.55 -> 165 | F19: =(CHOOSE('1. 가정'!$D$4,'1. 가정'!B27,'1. 가정'!C27,'1. 가정'!D27) - CHOOSE('1. 가정'!$D$4,'1. 가정'!B26,'1. 가정'!C26,'1. 가정'!D26))/4 -> 225 | G19: =(CHOOSE('1. 가정'!$D$4,'1. 가정'!B27,'1. 가정'!C27,'1. 가정'!D27) - CHOOSE('1. 가정'!$D$4,'1. 가정'!B26,'1. 가정'!C26,'1. 가정'!D26))/4 -> 225 | H19: =(CHOOSE('1. 가정'!$D$4,'1. 가정'!B27,'1. 가정'!C27,'1. 가정'!D27) - CHOOSE('1. 가정'!$D$4,'1. 가정'!B26,'1. 가정'!C26,'1. 가정'!D26))/4 -> 225 | I19: =(CHOOSE('1. 가정'!$D$4,'1. 가정'!B27,'1. 가정'!C27,'1. 가정'!D27) - CHOOSE('1. 가정'!$D$4,'1. 가정'!B26,'1. 가정'!C26,'1. 가정'!D26))/4 -> 225 | J19: =(CHOOSE('1. 가정'!$D$4,'1. 가정'!B28,'1. 가정'!C28,'1. 가정'!D28) - CHOOSE('1. 가정'!$D$4,'1. 가정'!B27,'1. 가정'!C27,'1. 가정'!D27))/4 -> 450 | K19: =(CHOOSE('1. 가정'!$D$4,'1. 가정'!B28,'1. 가정'!C28,'1. 가정'!D28) - CHOOSE('1. 가정'!$D$4,'1. 가정'!B27,'1. 가정'!C27,'1. 가정'!D27))/4 -> 450 | L19: =(CHOOSE('1. 가정'!$D$4,'1. 가정'!B28,'1. 가정'!C28,'1. 가정'!D28) - CHOOSE('1. 가정'!$D$4,'1. 가정'!B27,'1. 가정'!C27,'1. 가정'!D27))/4 -> 450 | M19: =(CHOOSE('1. 가정'!$D$4,'1. 가정'!B28,'1. 가정'!C28,'1. 가정'!D28) - CHOOSE('1. 가정'!$D$4,'1. 가정'!B27,'1. 가정'!C27,'1. 가정'!D27))/4 -> 450 | N19: =SUM(B19:M19) -> 3000
A20: AI 컨설팅 매출 (만) | B20: =B19*(CHOOSE('1. 가정'!$D$4,'1. 가정'!B25,'1. 가정'!C25,'1. 가정'!D25)) -> 0 | C20: =C19*(CHOOSE('1. 가정'!$D$4,'1. 가정'!B25,'1. 가정'!C25,'1. 가정'!D25)) -> 150 | D20: =D19*(CHOOSE('1. 가정'!$D$4,'1. 가정'!B25,'1. 가정'!C25,'1. 가정'!D25)) -> 525 | E20: =E19*(CHOOSE('1. 가정'!$D$4,'1. 가정'!B25,'1. 가정'!C25,'1. 가정'!D25)) -> 825 | F20: =F19*(CHOOSE('1. 가정'!$D$4,'1. 가정'!B25,'1. 가정'!C25,'1. 가정'!D25)) -> 1125 | G20: =G19*(CHOOSE('1. 가정'!$D$4,'1. 가정'!B25,'1. 가정'!C25,'1. 가정'!D25)) -> 1125 | H20: =H19*(CHOOSE('1. 가정'!$D$4,'1. 가정'!B25,'1. 가정'!C25,'1. 가정'!D25)) -> 1125 | I20: =I19*(CHOOSE('1. 가정'!$D$4,'1. 가정'!B25,'1. 가정'!C25,'1. 가정'!D25)) -> 1125 | J20: =J19*(CHOOSE('1. 가정'!$D$4,'1. 가정'!B25,'1. 가정'!C25,'1. 가정'!D25)) -> 2250 | K20: =K19*(CHOOSE('1. 가정'!$D$4,'1. 가정'!B25,'1. 가정'!C25,'1. 가정'!D25)) -> 2250 | L20: =L19*(CHOOSE('1. 가정'!$D$4,'1. 가정'!B25,'1. 가정'!C25,'1. 가정'!D25)) -> 2250 | M20: =M19*(CHOOSE('1. 가정'!$D$4,'1. 가정'!B25,'1. 가정'!C25,'1. 가정'!D25)) -> 2250 | N20: =SUM(B20:M20) -> 15000
A22: ④ B2C 프리미엄 구독
A23: 유료 구독자 (분기말) | B23: 0 | C23: 0 | D23: =(CHOOSE('1. 가정'!$D$4,'1. 가정'!B34,'1. 가정'!C34,'1. 가정'!D34))*0.3 -> 60 | E23: =CHOOSE('1. 가정'!$D$4,'1. 가정'!B34,'1. 가정'!C34,'1. 가정'!D34) -> 200 | F23: =CHOOSE('1. 가정'!$D$4,'1. 가정'!B34,'1. 가정'!C34,'1. 가정'!D34)+(CHOOSE('1. 가정'!$D$4,'1. 가정'!B35,'1. 가정'!C35,'1. 가정'!D35)-CHOOSE('1. 가정'!$D$4,'1. 가정'!B34,'1. 가정'!C34,'1. 가정'!D34))*0.2 -> 360 | G23: =CHOOSE('1. 가정'!$D$4,'1. 가정'!B34,'1. 가정'!C34,'1. 가정'!D34)+(CHOOSE('1. 가정'!$D$4,'1. 가정'!B35,'1. 가정'!C35,'1. 가정'!D35)-CHOOSE('1. 가정'!$D$4,'1. 가정'!B34,'1. 가정'!C34,'1. 가정'!D34))*0.45 -> 560 | H23: =CHOOSE('1. 가정'!$D$4,'1. 가정'!B34,'1. 가정'!C34,'1. 가정'!D34)+(CHOOSE('1. 가정'!$D$4,'1. 가정'!B35,'1. 가정'!C35,'1. 가정'!D35)-CHOOSE('1. 가정'!$D$4,'1. 가정'!B34,'1. 가정'!C34,'1. 가정'!D34))*0.7 -> 760 | I23: =CHOOSE('1. 가정'!$D$4,'1. 가정'!B35,'1. 가정'!C35,'1. 가정'!D35) -> 1000 | J23: =CHOOSE('1. 가정'!$D$4,'1. 가정'!B35,'1. 가정'!C35,'1. 가정'!D35)+(CHOOSE('1. 가정'!$D$4,'1. 가정'!B36,'1. 가정'!C36,'1. 가정'!D36)-CHOOSE('1. 가정'!$D$4,'1. 가정'!B35,'1. 가정'!C35,'1. 가정'!D35))*0.2 -> 1300 | K23: =CHOOSE('1. 가정'!$D$4,'1. 가정'!B35,'1. 가정'!C35,'1. 가정'!D35)+(CHOOSE('1. 가정'!$D$4,'1. 가정'!B36,'1. 가정'!C36,'1. 가정'!D36)-CHOOSE('1. 가정'!$D$4,'1. 가정'!B35,'1. 가정'!C35,'1. 가정'!D35))*0.45 -> 1675 | L23: =CHOOSE('1. 가정'!$D$4,'1. 가정'!B35,'1. 가정'!C35,'1. 가정'!D35)+(CHOOSE('1. 가정'!$D$4,'1. 가정'!B36,'1. 가정'!C36,'1. 가정'!D36)-CHOOSE('1. 가정'!$D$4,'1. 가정'!B35,'1. 가정'!C35,'1. 가정'!D35))*0.7 -> 2050 | M23: =CHOOSE('1. 가정'!$D$4,'1. 가정'!B36,'1. 가정'!C36,'1. 가정'!D36) -> 2500
A24: B2C 매출 (만) | B24: =(B23/2)*(CHOOSE('1. 가정'!$D$4,'1. 가정'!B33,'1. 가정'!C33,'1. 가정'!D33))*3/10000 -> 0 | C24: =((C23+B23)/2)*(CHOOSE('1. 가정'!$D$4,'1. 가정'!B33,'1. 가정'!C33,'1. 가정'!D33))*3/10000 -> 0 | D24: =((D23+C23)/2)*(CHOOSE('1. 가정'!$D$4,'1. 가정'!B33,'1. 가정'!C33,'1. 가정'!D33))*3/10000 -> 134.1 | E24: =((E23+D23)/2)*(CHOOSE('1. 가정'!$D$4,'1. 가정'!B33,'1. 가정'!C33,'1. 가정'!D33))*3/10000 -> 581.1 | F24: =((F23+E23)/2)*(CHOOSE('1. 가정'!$D$4,'1. 가정'!B33,'1. 가정'!C33,'1. 가정'!D33))*3/10000 -> 1251.6 | G24: =((G23+F23)/2)*(CHOOSE('1. 가정'!$D$4,'1. 가정'!B33,'1. 가정'!C33,'1. 가정'!D33))*3/10000 -> 2056.2 | H24: =((H23+G23)/2)*(CHOOSE('1. 가정'!$D$4,'1. 가정'!B33,'1. 가정'!C33,'1. 가정'!D33))*3/10000 -> 2950.2 | I24: =((I23+H23)/2)*(CHOOSE('1. 가정'!$D$4,'1. 가정'!B33,'1. 가정'!C33,'1. 가정'!D33))*3/10000 -> 3933.6 | J24: =((J23+I23)/2)*(CHOOSE('1. 가정'!$D$4,'1. 가정'!B33,'1. 가정'!C33,'1. 가정'!D33))*3/10000 -> 5140.5 | K24: =((K23+J23)/2)*(CHOOSE('1. 가정'!$D$4,'1. 가정'!B33,'1. 가정'!C33,'1. 가정'!D33))*3/10000 -> 6649.125 | L24: =((L23+K23)/2)*(CHOOSE('1. 가정'!$D$4,'1. 가정'!B33,'1. 가정'!C33,'1. 가정'!D33))*3/10000 -> 8325.375 | M24: =((M23+L23)/2)*(CHOOSE('1. 가정'!$D$4,'1. 가정'!B33,'1. 가정'!C33,'1. 가정'!D33))*3/10000 -> 10169.25 | N24: =SUM(B24:M24) -> 41191.05
A26: ═ 총 매출 (분기) ═ | B26: =B11+B16+B20+B24 -> 0 | C26: =C11+C16+C20+C24 -> 10716.667 | D26: =D11+D16+D20+D24 -> 5790.7667 | E26: =E11+E16+E20+E24 -> 1601.1417 | F26: =F11+F16+F20+F24 -> 2716.7656 | G26: =G11+G16+G20+G24 -> 3662.8615 | H26: =H11+H16+H20+H24 -> 4694.8199 | I26: =I11+I16+I20+I24 -> 5812.7294 | ... N26: =N11+N16+N20+N24 -> 79063.263
A28: 연도별 합계 | B28: Y1 (Q1~Q4) | C28: Y2 (Q5~Q8) | D28: Y3 (Q9~Q12) | E28: 3년 누계
A29: ① 정부 자금 | B29: =SUM(B11:E11) -> 15500 | C29: =SUM(F11:I11) -> 0 | D29: =SUM(J11:M11) -> 0 | E29: =B29+C29+D29 -> 15500
A30: ② B2B 지자체 | B30: =SUM(B16:E16) -> 393.375 | C30: =SUM(F16:I16) -> 2195.5765 | D30: =SUM(J16:M16) -> 4783.262 | E30: =B30+C30+D30 -> 7372.2135
A31: ③ AI 컨설팅 | B31: =SUM(B20:E20) -> 1500 | C31: =SUM(F20:I20) -> 4500 | D31: =SUM(J20:M20) -> 9000 | E31: =B31+C31+D31 -> 15000
A32: ④ B2C 프리미엄 | B32: =SUM(B24:E24) -> 715.2 | C32: =SUM(F24:I24) -> 10191.6 | D32: =SUM(J24:M24) -> 30284.25 | E32: =B32+C32+D32 -> 41191.05
A34: 총 매출 | B34: =SUM(B29:B32) -> 18108.575 | C34: =SUM(C29:C32) -> 16887.177 | D34: =SUM(D29:D32) -> 44067.512 | E34: =SUM(E29:E32) -> 79063.263

Sheet 3. 비용
A1: 비용 — 연도별 (3개 시나리오 공통)
A3: 항목 | B3: Y1 (연) | C3: Y2 (연) | D3: Y3 (연) | E3: 3년 누계
A4: 호스팅·인프라 | B4: ='1. 가정'!B41*12 -> 120 | C4: ='1. 가정'!C41*12 -> 360 | D4: ='1. 가정'!D41*12 -> 720 | E4: =SUM(B4:D4) -> 1200
A5: AI API 운영 | B5: ='1. 가정'!B42*12 -> 60 | C5: ='1. 가정'!C42*12 -> 360 | D5: ='1. 가정'!D42*12 -> 1200 | E5: =SUM(B5:D5) -> 1620
A6: 도메인·SaaS | B6: ='1. 가정'!B43*12 -> 24 | C6: ='1. 가정'!C43*12 -> 60 | D6: ='1. 가정'!D43*12 -> 120 | E6: =SUM(B6:D6) -> 204
A7: 마케팅·콘텐츠 | B7: ='1. 가정'!B44*12 -> 240 | C7: ='1. 가정'!C44*12 -> 1200 | D7: ='1. 가정'!D44*12 -> 2400 | E7: =SUM(B7:D7) -> 3840
A8: 운영자 인건비 | B8: ='1. 가정'!B45*12 -> 0 | C8: ='1. 가정'!C45*12 -> 3600 | D8: ='1. 가정'!D45*12 -> 6000 | E8: =SUM(B8:D8) -> 9600
A9: 외주 인건비 | B9: ='1. 가정'!B46*12 -> 0 | C9: ='1. 가정'!C46*12 -> 1200 | D9: ='1. 가정'!D46*12 -> 2400 | E9: =SUM(B9:D9) -> 3600
A10: 고정 비용 합계 | B10: =SUM(B4:B9) -> 444 | C10: =SUM(C4:C9) -> 6780 | D10: =SUM(D4:D9) -> 12840 | E10: =SUM(E4:E9) -> 20064
A12: 변동 비용
A13: 결제 PG 수수료 (3%) | B13: =('2. 매출 빌드업'!B31+'2. 매출 빌드업'!B32)*0.03 -> 66.456 | C13: =('2. 매출 빌드업'!C31+'2. 매출 빌드업'!C32)*0.03 -> 440.748 | D13: =('2. 매출 빌드업'!D31+'2. 매출 빌드업'!D32)*0.03 -> 1178.5275 | E13: =SUM(B13:D13) -> 1685.7315
A14: AI 토큰 (사용량 비례) | B14: =SUM('2. 매출 빌드업'!B19:E19)*0.05 -> 15 | C14: =SUM('2. 매출 빌드업'!F19:I19)*0.05 -> 45 | D14: =SUM('2. 매출 빌드업'!J19:M19)*0.05 -> 90 | E14: =SUM(B14:D14) -> 150
A16: 변동 비용 합계 | B16: =SUM(B13:B14) -> 81.456 | C16: =SUM(C13:C14) -> 485.748 | D16: =SUM(D13:D14) -> 1268.5275 | E16: =SUM(E13:E14) -> 1835.7315
A18: ═ 총 비용 ═ | B18: =B10+B16 -> 525.456 | C18: =C10+C16 -> 7265.748 | D18: =D10+D16 -> 14108.528 | E18: =E10+E16 -> 21899.732

Sheet 4. P&L 요약
A1: P&L 요약 — 3년 손익
A2: 현재 시나리오: | B2: ='1. 가정'!E4 -> 기본
A4: 항목 | B4: Y1 | C4: Y2 | D4: Y3 | E4: 3년 누계
A5: 매출 | B5: ='2. 매출 빌드업'!B34 -> 18108.575 | C5: ='2. 매출 빌드업'!C34 -> 16887.177 | D5: ='2. 매출 빌드업'!D34 -> 44067.512 | E5: =SUM(B5:D5) -> 79063.263
A6: 비용 | B6: ='3. 비용'!B18 -> 525.456 | C6: ='3. 비용'!C18 -> 7265.748 | D6: ='3. 비용'!D18 -> 14108.528 | E6: =SUM(B6:D6) -> 21899.732
A7: 영업이익 | B7: =B5-B6 -> 17583.119 | C7: =C5-C6 -> 9621.4285 | D7: =D5-D6 -> 29958.984 | E7: =E5-E6 -> 57163.532
A8: 영업이익률 | B8: =IFERROR(B7/B5,0) -> 0.97098303 | C8: =IFERROR(C7/C5,0) -> 0.56974761 | D8: =IFERROR(D7/D5,0) -> 0.67984289 | E8: =IFERROR(E7/E5,0) -> 0.72301002
A10: 매출 구성 (Y3 기준)
A11: ① 정부 자금 | B11: ='2. 매출 빌드업'!D29 -> 0 | C11: =IFERROR(B11/$D$5,0) -> 0
A12: ② B2B 지자체 | B12: ='2. 매출 빌드업'!D30 -> 4783.262 | C12: =IFERROR(B12/$D$5,0) -> 0.10854395
A13: ③ AI 컨설팅 | B13: ='2. 매출 빌드업'!D31 -> 9000 | C13: =IFERROR(B13/$D$5,0) -> 0.20423209
A14: ④ B2C 프리미엄 | B14: ='2. 매출 빌드업'!D32 -> 30284.25 | C14: =IFERROR(B14/$D$5,0) -> 0.68722396

Sheet 5. 시나리오 비교
A1: 시나리오 비교 — 보수 vs 기본 vs 공격
A2: 각 시나리오를 분리해 비교. 가정 시트의 D4 토글을 바꿔도 이 표는 고정.
A4: 지표 (3년 누계) | B4: 보수 | C4: 기본 | D4: 공격
A5: ① 정부 자금 누계 (만) | B5: =SUM('1. 가정'!B8:B11) -> 5500 | C5: =SUM('1. 가정'!C8:C11) -> 15500 | D5: =SUM('1. 가정'!D8:D11) -> 30500
A6: ② B2B 지자체 누계 (만) | B6: =('1. 가정'!B16)*((('1. 가정'!B17)*0.5+('1. 가정'!B18)*1.5+('1. 가정'!B19)*2.5)) -> 3500 | C6: =('1. 가정'!C16)*((('1. 가정'!C17)*0.5+('1. 가정'!C18)*1.5+('1. 가정'!C19)*2.5)) -> 12000 | D6: =('1. 가정'!D16)*((('1. 가정'!D17)*0.5+('1. 가정'!D18)*1.5+('1. 가정'!D19)*2.5)) -> 42750
A7: ③ AI 컨설팅 누계 (만) | B7: =('1. 가정'!B25)*(('1. 가정'!B26)+('1. 가정'!B27)+('1. 가정'!B28)) -> 4500 | C7: =('1. 가정'!C25)*(('1. 가정'!C26)+('1. 가정'!C27)+('1. 가정'!C28)) -> 22500 | D7: =('1. 가정'!D25)*(('1. 가정'!D26)+('1. 가정'!D27)+('1. 가정'!D28)) -> 72000
A8: ④ B2C 프리미엄 누계 (만) | B8: =('1. 가정'!B33)/10000*('1. 가정'!B36)*12*0.6 -> 5702.4 | C8: =('1. 가정'!C33)/10000*('1. 가정'!C36)*12*0.6 -> 26820 | D8: =('1. 가정'!D33)/10000*('1. 가정'!D36)*12*0.6 -> 85968
A9: ═ 3년 누계 매출 | B9: =SUM(B5:B8) -> 19202.4 | C9: =SUM(C5:C8) -> 76820 | D9: =SUM(D5:D8) -> 231218
A11: 3년 누계 비용 (만) | B11: ='1. 가정'!B48*3 -> 1332 | C11: ='1. 가정'!C48*3 -> 20340 | D11: ='1. 가정'!D48*3 -> 38520
A13: ═ 3년 누계 영업이익 | B13: =B9-B11 -> 17870.4 | C13: =C9-C11 -> 56480 | D13: =D9-D11 -> 192698
A14: 영업이익률 | B14: =IFERROR(B13/B9,0) -> 0.93063367 | C14: =IFERROR(C13/C9,0) -> 0.7352252 | D14: =IFERROR(D13/D9,0) -> 0.83340397
A16: ▶ 보수 = 가장 낮은 채택률, B2B 1곳 시작
A17: ▶ 기본 = 실현 가능성 높은 베이스라인
A18: ▶ 공격 = B2B 빠른 확장 + B2C 성공 가정
